Workbook

Sheet Test Case Register
A1: AMC Core — Master Business Scenarios Test Case Register
A2: DocTypes: AMC Customers | AMC Contract | Vendor | Attendance | Expense Claim | Leave Application | Service Call | Total: 320 test cases | 27 Feb 2026
A4: Test ID | B4: DocType | C4: Module | D4: Test Case Title | E4: Priority | F4: Business Rule | G4: Status | H4: Executed By | I4: Execution Date | J4: Actual Result | K4: Defect ID | L4: Notes
A5: ▌ AMC Customers
A6: CUST-001 | B6: AMC Customers | C6: Customer Creation & Basic Details | D6: Create customer with Customer Name only (minimum required) | E6: Critical | F6: BR-CUST-01 | G6: Not Run
A7: CUST-002 | B7: AMC Customers | C7: Customer Creation & Basic Details | D7: Create Company customer with all basic fields (Name, Type, GST, PAN) | E7: Critical | F7: BR-CUST-01, BR-CUST-02 | G7: Not Run
A8: CUST-003 | B8: AMC Customers | C8: Customer Creation & Basic Details | D8: Create Individual customer type | E8: High | F8: BR-CUST-02 | G8: Not Run
A9: CUST-004 | B9: AMC Customers | C9: Customer Creation & Basic Details | D9: Create Partnership customer type | E9: High | F9: BR-CUST-02 | G9: Not Run
A10: CUST-005 | B10: AMC Customers | C10: GST Validation | D10: Valid 15-character GSTIN is accepted | E10: Critical | F10: BR-CUST-03 | G10: Not Run
A11: CUST-006 | B11: AMC Customers | C11: GST Validation | D11: Invalid GST format is rejected with specific error message | E11: Critical | F11: BR-CUST-03 | G11: Not Run
A12: CUST-007 | B12: AMC Customers | C12: GST Validation | D12: Duplicate GSTIN across two customers is blocked | E12: Critical | F12: BR-CUST-04 | G12: Not Run
A13: CUST-008 | B13: AMC Customers | C13: GST Validation | D13: GST field can be left blank (optional for Individual) | E13: High | F13: BR-CUST-03 | G13: Not Run
A14: CUST-009 | B14: AMC Customers | C14: GST Validation | D14: Duplicate PAN across two customers is blocked | E14: High | F14: BR-CUST-05 | G14: Not Run
A15: CUST-010 | B15: AMC Customers | C15: Branch Locations | D15: Add single branch location to customer | E15: Critical | F15: BR-CUST-06 | G15: Not Run
A16: CUST-011 | B16: AMC Customers | C16: Branch Locations | D16: Add multiple branch locations to same customer | E16: High | F16: BR-CUST-06 | G16: Not Run
A17: CUST-012 | B17: AMC Customers | C17: Branch Locations | D17: Delete a branch location row | E17: Medium | F17: BR-CUST-06 | G17: Not Run
... A26: CUST-021 | B26: AMC Customers | C26: Data Integrity | D26: Deleting customer with active contracts is blocked | E26: High | F26: BR-CUST-10 | G26: Not Run
A27: ▌ AMC Contract
A28: CON-001 | B28: AMC Contract | C28: Contract Creation | D28: Create AMC Contract with all mandatory fields | E28: Critical | F28: BR-CON-01 | G28: Not Run
A29: CON-002 | B29: AMC Contract | C29: Contract Creation | D29: Start Date is mandatory — save fails without it | E29: Critical | F29: BR-CON-01 | G29: Not Run
A30: CON-003 | B30: AMC Contract | C30: Contract Creation | D30: End Date is mandatory — save fails without it | E30: Critical | F30: BR-CON-01 | G30: Not Run
A31: CON-004 | B31: AMC Contract | C31: Contract Creation | D31: No of Services is mandatory — save fails without it | E31: Critical | F31: BR-CON-01 | G31: Not Run
A32: CON-005 | B32: AMC Contract | C32: Contract Creation | D32: Auto-naming follows AMC-.YY.MM.-.#### series | E32: High | F32: BR-CON-02 | G32: Not Run
A33: CON-006 | B33: AMC Contract | C33: Contract Date Logic | D33: End Date before Start Date is rejected | E33: Critical | F33: BR-CON-03 | G33: Not Run
A34: CON-007 | B34: AMC Contract | C34: Contract Date Logic | D34: Same Start and End Date is valid (single-day contract) | E34: High | F34: BR-CON-03 | G34: Not Run
A35: CON-008 | B35: AMC Contract | C35: Contract Date Logic | D35: Multi-year contract is valid (e.g., 2 years) | E35: High | F35: BR-CON-03 | G35: Not Run
A36: CON-009 | B36: AMC Contract | C36: Service Count & Schedule | D36: 4 services Jan-Dec creates exactly 4 Maintenance Schedule rows | E36: Critical | F36: BR-CON-04 | G36: Not Run
A37: CON-010 | B37: AMC Contract | C37: Service Count & Schedule | D37: 12 services creates 12 monthly Maintenance Schedule rows | E37: Critical | F37: BR-CON-04 | G37: Not Run
A38: CON-011 | B38: AMC Contract | C38: Service Count & Schedule | D38: 1 service creates exactly 1 Maintenance Schedule row | E38: Critical | F38: BR-CON-04 | G38: Not Run
A39: CON-012 | B39: AMC Contract | C39: Service Count & Schedule | D39: All schedule dates fall within contract Start-End range | E39: Critical | F39: BR-CON-05 | G39: Not Run
... A59: CON-032 | B59: AMC Contract | C59: Cross-DocType Integration | D59: Technician cannot cancel or delete AMC Contract | E59: Critical | F59: BR-CON-14 | G59: Not Run
A60: ▌ Vendor
A61: VEN-001 | B61: Vendor | C61: Vendor Creation & Basic Details | D61: Create Vendor with Vendor Name only (mandatory field) | E61: Critical | F61: BR-VEN-01 | G61: Not Run
A62: VEN-002 | B62: Vendor | C62: Vendor Creation & Basic Details | D62: Create Vendor with all basic fields (Name, Type, PAN) | E62: Critical | F62: BR-VEN-01, BR-VEN-02 | G62: Not Run
A63: VEN-003 | B63: Vendor | C63: Vendor Creation & Basic Details | D63: Create Vendor with Type as Company | E63: High | F63: BR-VEN-02 | G63: Not Run
A64: VEN-004 | B64: Vendor | C64: Vendor Creation & Basic Details | D64: Create Vendor with Type as Individual | E64: High | F64: BR-VEN-02 | G64: Not Run
A65: VEN-005 | B65: Vendor | C65: Primary Contact Details | D65: Add Primary Contact Person | E65: Critical | F65: BR-VEN-03 | G65: Not Run
A66: VEN-006 | B66: Vendor | C66: Primary Contact Details | D66: Valid phone number format in Mobile No field | E66: High | F66: BR-VEN-03 | G66: Not Run
A67: VEN-007 | B67: Vendor | C67: Primary Contact Details | D67: Invalid phone number format is rejected | E67: Critical | F67: BR-VEN-03 | G67: Not Run
A68: VEN-008 | B68: Vendor | C68: Primary Contact Details | D68: Valid email format is accepted | E68: High | F68: BR-VEN-03 | G68: Not Run
...

Sheet Run Tracker
A1: AMC Core — Master Test Execution Run Tracker
A2: Each Run column = one full execution cycle. Formulas auto-calculate pass rate per test case.
A4: Test ID | B4: DocType | C4: Module | D4: Title | E4: Priority | F4: Run 1 | G4: Run 2 | H4: Run 3 | I4: Run 4 | J4: Run 5 | K4: Run 6 | L4: Total Runs | M4: Pass | N4: Fail | O4: Pass Rate
A5: ▌ AMC Customers
A6: CUST-001 | B6: AMC Customers | C6: Customer Creation & Basic Details | D6: Create customer with Customer Name only (minimum required) | E6: Critical | F6: Not Run | G6: Not Run | H6: Not Run | I6: Not Run | J6: Not Run | K6: Not Run | L6: =COUNTA(F6:K6) -> 6 | M6: =COUNTIF(F6:K6,"Pass") -> 0 | N6: =COUNTIF(F6:K6,"Fail") -> 0 | O6: =IF(M6=0,"-",M6/L6) -> -
A7: CUST-002 | B7: AMC Customers | C7: Customer Creation & Basic Details | D7: Create Company customer with all basic fields (Name, Type, GST, PAN) | E7: Critical | F7: Not Run | G7: Not Run | H7: Not Run | I7: Not Run | J7: Not Run | K7: Not Run | L7: =COUNTA(F7:K7) -> 6 | M7: =COUNTIF(F7:K7,"Pass") -> 0 | N7: =COUNTIF(F7:K7,"Fail") -> 0 | O7: =IF(M7=0,"-",M7/L7) -> -
A8: CUST-003 | B8: AMC Customers | C8: Customer Creation & Basic Details | D8: Create Individual customer type | E8: High | F8: Not Run | G8: Not Run | H8: Not Run | I8: Not Run | J8: Not Run | K8: Not Run | L8: =COUNTA(F8:K8) -> 6 | M8: =COUNTIF(F8:K8,"Pass") -> 0 | N8: =COUNTIF(F8:K8,"Fail") -> 0 | O8: =IF(M8=0,"-",M8/L8) -> -
A9: CUST-004 | B9: AMC Customers | C9: Customer Creation & Basic Details | D9: Create Partnership customer type | E9: High | F9: Not Run | G9: Not Run | H9: Not Run | I9: Not Run | J9: Not Run | K9: Not Run | L9: =COUNTA(F9:K9) -> 6 | M9: =COUNTIF(F9:K9,"Pass") -> 0 | N9: =COUNTIF(F9:K9,"Fail") -> 0 | O9: =IF(M9=0,"-",M9/L9) -> -
A10: CUST-005 | B10: AMC Customers | C10: GST Validation | D10: Valid 15-character GSTIN is accepted | E10: Critical | F10: Not Run | G10: Not Run | H10: Not Run | I10: Not Run | J10: Not Run | K10: Not Run | L10: =COUNTA(F10:K10) -> 6 | M10: =COUNTIF(F10:K10,"Pass") -> 0 | N10: =COUNTIF(F10:K10,"Fail") -> 0 | O10: =IF(M10=0,"-",M10/L10) -> -
A11: CUST-006 | B11: AMC Customers | C11: GST Validation | D11: Invalid GST format is rejected with specific error message | E11: Critical | F11: Not Run | G11: Not Run | H11: Not Run | I11: Not Run | J11: Not Run | K11: Not Run | L11: =COUNTA(F11:K11) -> 6 | M11: =COUNTIF(F11:K11,"Pass") -> 0 | N11: =COUNTIF(F11:K11,"Fail") -> 0 | O11: =IF(M11=0,"-",M11/L11) -> -
A12: CUST-007 | B12: AMC Customers | C12: GST Validation | D12: Duplicate GSTIN across two customers is blocked | E12: Critical | F12: Not Run | G12: Not Run | H12: Not Run | I12: Not Run | J12: Not Run | K12: Not Run | L12: =COUNTA(F12:K12) -> 6 | M12: =COUNTIF(F12:K12,"Pass") -> 0 | N12: =COUNTIF(F12:K12,"Fail") -> 0 | O12: =IF(M12=0,"-",M12/L12) -> -
A13: CUST-008 | B13: AMC Customers | C13: GST Validation | D13: GST field can be left blank (optional for Individual) | E13: High | F13: Not Run | G13: Not Run | H13: Not Run | I13: Not Run | J13: Not Run | K13: Not Run | L13: =COUNTA(F13:K13) -> 6 | M13: =COUNTIF(F13:K13,"Pass") -> 0 | N13: =COUNTIF(F13:K13,"Fail") -> 0 | O13: =IF(M13=0,"-",M13/L13) -> -
A14: CUST-009 | B14: AMC Customers | C14: GST Validation | D14: Duplicate PAN across two customers is blocked | E14: High | F14: Not Run | G14: Not Run | H14: Not Run | I14: Not Run | J14: Not Run | K14: Not Run | L14: =COUNTA(F14:K14) -> 6 | M14: =COUNTIF(F14:K14,"Pass") -> 0 | N14: =COUNTIF(F14:K14,"Fail") -> 0 | O14: =IF(M14=0,"-",M14/L14) -> -
A15: CUST-010 | B15: AMC Customers | C15: Branch Locations | D15: Add single branch location to customer | E15: Critical | F15: Not Run | G15: Not Run | H15: Not Run | I15: Not Run | J15: Not Run | K15: Not Run | L15: =COUNTA(F15:K15) -> 6 | M15: =COUNTIF(F15:K15,"Pass") -> 0 | N15: =COUNTIF(F15:K15,"Fail") -> 0 | O15: =IF(M15=0,"-",M15/L15) -> -
A16: CUST-011 | B16: AMC Customers | C16: Branch Locations | D16: Add multiple branch locations to same customer | E16: High | F16: Not Run | G16: Not Run | H16: Not Run | I16: Not Run | J16: Not Run | K16: Not Run | L16: =COUNTA(F16:K16) -> 6 | M16: =COUNTIF(F16:K16,"Pass") -> 0 | N16: =COUNTIF(F16:K16,"Fail") -> 0 | O16: =IF(M16=0,"-",M16/L16) -> -
A17: CUST-012 | B17: AMC Customers | C17: Branch Locations | D17: Delete a branch location row | E17: Medium | F17: Not Run | G17: Not Run | H17: Not Run | I17: Not Run | J17: Not Run | K17: Not Run | L17: =COUNTA(F17:K17) -> 6 | M17: =COUNTIF(F17:K17,"Pass") -> 0 | N17: =COUNTIF(F17:K17,"Fail") -> 0 | O17: =IF(M17=0,"-",M17/L17) -> -
... A26: CUST-021 | B26: AMC Customers | C26: Data Integrity | D26: Deleting customer with active contracts is blocked | E26: High | F26: Not Run | G26: Not Run | H26: Not Run | I26: Not Run | J26: Not Run | K26: Not Run | L26: =COUNTA(F26:K26) -> 6 | M26: =COUNTIF(F26:K26,"Pass") -> 0 | N26: =COUNTIF(F26:K26,"Fail") -> 0 | O26: =IF(M26=0,"-",M26/L26) -> -
A27: ▌ AMC Contract
A28: CON-001 | B28: AMC Contract | C28: Contract Creation | D28: Create AMC Contract with all mandatory fields | E28: Critical | F28: Not Run | G28: Not Run | H28: Not Run | I28: Not Run | J28: Not Run | K28: Not Run | L28: =COUNTA(F28:K28) -> 6 | M28: =COUNTIF(F28:K28,"Pass") -> 0 | N28: =COUNTIF(F28:K28,"Fail") -> 0 | O28: =IF(M28=0,"-",M28/L28) -> -
A29: CON-002 | B29: AMC Contract | C29: Contract Creation | D29: Start Date is mandatory — save fails without it | E29: Critical | F29: Not Run | G29: Not Run | H29: Not Run | I29: Not Run | J29: Not Run | K29: Not Run | L29: =COUNTA(F29:K29) -> 6 | M29: =COUNTIF(F29:K29,"Pass") -> 0 | N29: =COUNTIF(F29:K29,"Fail") -> 0 | O29: =IF(M29=0,"-",M29/L29) -> -
A30: CON-003 | B30: AMC Contract | C30: Contract Creation | D30: End Date is mandatory — save fails without it | E30: Critical | F30: Not Run | G30: Not Run | H30: Not Run | I30: Not Run | J30: Not Run | K30: Not Run | L30: =COUNTA(F30:K30) -> 6 | M30: =COUNTIF(F30:K30,"Pass") -> 0 | N30: =COUNTIF(F30:K30,"Fail") -> 0 | O30: =IF(M30=0,"-",M30/L30) -> -
A31: CON-004 | B31: AMC Contract | C31: Contract Creation | D31: No of Services is mandatory — save fails without it | E31: Critical | F31: Not Run | G31: Not Run | H31: Not Run | I31: Not Run | J31: Not Run | K31: Not Run | L31: =COUNTA(F31:K31) -> 6 | M31: =COUNTIF(F31:K31,"Pass") -> 0 | N31: =COUNTIF(F31:K31,"Fail") -> 0 | O31: =IF(M31=0,"-",M31/L31) -> -
A32: CON-005 | B32: AMC Contract | C32: Contract Creation | D32: Auto-naming follows AMC-.YY.MM.-.#### series | E32: High | F32: Not Run | G32: Not Run | H32: Not Run | I32: Not Run | J32: Not Run | K32: Not Run | L32: =COUNTA(F32:K32) -> 6 | M32: =COUNTIF(F32:K32,"Pass") -> 0 | N32: =COUNTIF(F32:K32,"Fail") -> 0 | O32: =IF(M32=0,"-",M32/L32) -> -
A33: CON-006 | B33: AMC Contract | C33: Contract Date Logic | D33: End Date before Start Date is rejected | E33: Critical | F33: Not Run | G33: Not Run | H33: Not Run | I33: Not Run | J33: Not Run | K33: Not Run | L33: =COUNTA(F33:K33) -> 6 | M33: =COUNTIF(F33:K33,"Pass") -> 0 | N33: =COUNTIF(F33:K33,"Fail") -> 0 | O33: =IF(M33=0,"-",M33/L33) -> -
A34: CON-007 | B34: AMC Contract | C34: Contract Date Logic | D34: Same Start and End Date is valid (single-day contract) | E34: High | F34: Not Run | G34: Not Run | H34: Not Run | I34: Not Run | J34: Not Run | K34: Not Run | L34: =COUNTA(F34:K34) -> 6 | M34: =COUNTIF(F34:K34,"Pass") -> 0 | N34: =COUNTIF(F34:K34,"Fail") -> 0 | O34: =IF(M34=0,"-",M34/L34) -> -
A35: CON-008 | B35: AMC Contract | C35: Contract Date Logic | D35: Multi-year contract is valid (e.g., 2 years) | E35: High | F35: Not Run | G35: Not Run | H35: Not Run | I35: Not Run | J35: Not Run | K35: Not Run | L35: =COUNTA(F35:K35) -> 6 | M35: =COUNTIF(F35:K35,"Pass") -> 0 | N35: =COUNTIF(F35:K35,"Fail") -> 0 | O35: =IF(M35=0,"-",M35/L35) -> -
A36: CON-009 | B36: AMC Contract | C36: Service Count & Schedule | D36: 4 services Jan-Dec creates exactly 4 Maintenance Schedule rows | E36: Critical | F36: Not Run | G36: Not Run | H36: Not Run | I36: Not Run | J36: Not Run | K36: Not Run | L36: =COUNTA(F36:K36) -> 6 | M36: =COUNTIF(F36:K36,"Pass") -> 0 | N36: =COUNTIF(F36:K36,"Fail") -> 0 | O36: =IF(M36=0,"-",M36/L36) -> -
A37: CON-010 | B37: AMC Contract | C37: Service Count & Schedule | D37: 12 services creates 12 monthly Maintenance Schedule rows | E37: Critical | F37: Not Run | G37: Not Run | H37: Not Run | I37: Not Run | J37: Not Run | K37: Not Run | L37: =COUNTA(F37:K37) -> 6 | M37: =COUNTIF(F37:K37,"Pass") -> 0 | N37: =COUNTIF(F37:K37,"Fail") -> 0 | O37: =IF(M37=0,"-",M37/L37) -> -
A38: CON-011 | B38: AMC Contract | C38: Service Count & Schedule | D38: 1 service creates exactly 1 Maintenance Schedule row | E38: Critical | F38: Not Run | G38: Not Run | H38: Not Run | I38: Not Run | J38: Not Run | K38: Not Run | L38: =COUNTA(F38:K38) -> 6 | M38: =COUNTIF(F38:K38,"Pass") -> 0 | N38: =COUNTIF(F38:K38,"Fail") -> 0 | O38: =IF(M38=0,"-",M38/L38) -> -
A39: CON-012 | B39: AMC Contract | C39: Service Count & Schedule | D39: All schedule dates fall within contract Start-End range | E39: Critical | F39: Not Run | G39: Not Run | H39: Not Run | I39: Not Run | J39: Not Run | K39: Not Run | L39: =COUNTA(F39:K39) -> 6 | M39: =COUNTIF(F39:K39,"Pass") -> 0 | N39: =COUNTIF(F39:K39,"Fail") -> 0 | O39: =IF(M39=0,"-",M39/L39) -> -
... A59: CON-032 | B59: AMC Contract | C59: Cross-DocType Integration | D59: Technician cannot cancel or delete AMC Contract | E59: Critical | F59: Not Run | G59: Not Run | H59: Not Run | I59: Not Run | J59: Not Run | K59: Not Run | L59: =COUNTA(F59:K59) -> 6 | M59: =COUNTIF(F59:K59,"Pass") -> 0 | N59: =COUNTIF(F59:K59,"Fail") -> 0 | O59: =IF(M59=0,"-",M59/L59) -> -
A60: ▌ Vendor
A61: VEN-001 | B61: Vendor | C61: Vendor Creation & Basic Details | D61: Create Vendor with Vendor Name only (mandatory field) | E61: Critical | F61: Not Run | G61: Not Run | H61: Not Run | I61: Not Run | J61: Not Run | K61: Not Run | L61: =COUNTA(F61:K61) -> 6 | M61: =COUNTIF(F61:K61,"Pass") -> 0 | N61: =COUNTIF(F61:K61,"Fail") -> 0 | O61: =IF(M61=0,"-",M61/L61) -> -
A62: VEN-002 | B62: Vendor | C62: Vendor Creation & Basic Details | D62: Create Vendor with all basic fields (Name, Type, PAN) | E62: Critical | F62: Not Run | G62: Not Run | H62: Not Run | I62: Not Run | J62: Not Run | K62: Not Run | L62: =COUNTA(F62:K62) -> 6 | M62: =COUNTIF(F62:K62,"Pass") -> 0 | N62: =COUNTIF(F62:K62,"Fail") -> 0 | O62: =IF(M62=0,"-",M62/L62) -> -
A63: VEN-003 | B63: Vendor | C63: Vendor Creation & Basic Details | D63: Create Vendor with Type as Company | E63: High | F63: Not Run | G63: Not Run | H63: Not Run | I63: Not Run | J63: Not Run | K63: Not Run | L63: =COUNTA(F63:K63) -> 6 | M63: =COUNTIF(F63:K63,"Pass") -> 0 | N63: =COUNTIF(F63:K63,"Fail") -> 0 | O63: =IF(M63=0,"-",M63/L63) -> -
A64: VEN-004 | B64: Vendor | C64: Vendor Creation & Basic Details | D64: Create Vendor with Type as Individual | E64: High | F64: Not Run | G64: Not Run | H64: Not Run | I64: Not Run | J64: Not Run | K64: Not Run | L64: =COUNTA(F64:K64) -> 6 | M64: =COUNTIF(F64:K64,"Pass") -> 0 | N64: =COUNTIF(F64:K64,"Fail") -> 0 | O64: =IF(M64=0,"-",M64/L64) -> -
A65: VEN-005 | B65: Vendor | C65: Primary Contact Details | D65: Add Primary Contact Person | E65: Critical | F65: Not Run | G65: Not Run | H65: Not Run | I65: Not Run | J65: Not Run | K65: Not Run | L65: =COUNTA(F65:K65) -> 6 | M65: =COUNTIF(F65:K65,"Pass") -> 0 | N65: =COUNTIF(F65:K65,"Fail") -> 0 | O65: =IF(M65=0,"-",M65/L65) -> -
A66: VEN-006 | B66: Vendor | C66: Primary Contact Details | D66: Valid phone number format in Mobile No field | E66: High | F66: Not Run | G66: Not Run | H66: Not Run | I66: Not Run | J66: Not Run | K66: Not Run | L66: =COUNTA(F66:K66) -> 6 | M66: =COUNTIF(F66:K66,"Pass") -> 0 | N66: =COUNTIF(F66:K66,"Fail") -> 0 | O66: =IF(M66=0,"-",M66/L66) -> -
A67: VEN-007 | B67: Vendor | C67: Primary Contact Details | D67: Invalid phone number format is rejected | E67: Critical | F67: Not Run | G67: Not Run | H67: Not Run | I67: Not Run | J67: Not Run | K67: Not Run | L67: =COUNTA(F67:K67) -> 6 | M67: =COUNTIF(F67:K67,"Pass") -> 0 | N67: =COUNTIF(F67:K67,"Fail") -> 0 | O67: =IF(M67=0,"-",M67/L67) -> -
A68: VEN-008 | B68: Vendor | C68: Primary Contact Details | D68: Valid email format is accepted | E68: High | F68: Not Run | G68: Not Run | H68: Not Run | I68: Not Run | J68: Not Run | K68: Not Run | L68: =COUNTA(F68:K68) -> 6 | M68: =COUNTIF(F68:K68,"Pass") -> 0 | N68: =COUNTIF(F68:K68,"Fail") -> 0 | O68: =IF(M68=0,"-",M68/L68) -> -
...

Sheet Run Summary
A1: AMC Core — Master Execution Summary Dashboard
A2: Live dashboard — all metrics auto-update as Test Case Register statuses are filled in.
A4: Total TCs | C4: Not Run | E4: Pass | G4: Fail | I4: Blocked | K4: Pass Rate
A5: =COUNTA('Test Case Register'!A5:A700)-COUNTIF('Test Case Register'!A5:A700,"▌*") -> 320 | C5: =COUNTIF('Test Case Register'!G5:G700,"Not Run") -> 320 | E5: =COUNTIF('Test Case Register'!G5:G700,"Pass") -> 0 | G5: =COUNTIF('Test Case Register'!G5:G700,"Fail") -> 0 | I5: =COUNTIF('Test Case Register'!G5:G700,"Blocked") -> 0 | K5: =IF(COUNTIF('Test Case Register'!G5:G700,"Pass")+COUNTIF('Test Case Register'!G5:G700,"Fail")=0,0,COUNTIF('Test Case Register'!G5:G700,"Pass")/(COUNTIF('Test Case Register'!G5:G700,"Pass")+COUNTIF('Test Case Register'!G5:G700,"Fail"))) -> 0
A7: Results by DocType
A8: DocType | C8: Total | E8: Pass | G8: Fail | I8: Blocked | K8: Pass Rate
A9: AMC Customers | C9: 21 | E9: =COUNTIFS('Test Case Register'!B5:B700,"AMC Customers",'Test Case Register'!G5:G700,"Pass") -> 0 | G9: =COUNTIFS('Test Case Register'!B5:B700,"AMC Customers",'Test Case Register'!G5:G700,"Fail") -> 0 | I9: =COUNTIFS('Test Case Register'!B5:B700,"AMC Customers",'Test Case Register'!G5:G700,"Blocked") -> 0 | K9: =IF(E9+G9=0,"-",E9/(E9+G9)) -> -
A10: AMC Contract | C10: 32 | E10: =COUNTIFS('Test Case Register'!B5:B700,"AMC Contract",'Test Case Register'!G5:G700,"Pass") -> 0 | G10: =COUNTIFS('Test Case Register'!B5:B700,"AMC Contract",'Test Case Register'!G5:G700,"Fail") -> 0 | I10: =COUNTIFS('Test Case Register'!B5:B700,"AMC Contract",'Test Case Register'!G5:G700,"Blocked") -> 0 | K10: =IF(E10+G10=0,"-",E10/(E10+G10)) -> -
A11: Vendor | C11: 40 | E11: =COUNTIFS('Test Case Register'!B5:B700,"Vendor",'Test Case Register'!G5:G700,"Pass") -> 0 | G11: =COUNTIFS('Test Case Register'!B5:B700,"Vendor",'Test Case Register'!G5:G700,"Fail") -> 0 | I11: =COUNTIFS('Test Case Register'!B5:B700,"Vendor",'Test Case Register'!G5:G700,"Blocked") -> 0 | K11: =IF(E11+G11=0,"-",E11/(E11+G11)) -> -
A12: Attendance | C12: 52 | E12: =COUNTIFS('Test Case Register'!B5:B700,"Attendance",'Test Case Register'!G5:G700,"Pass") -> 0 | G12: =COUNTIFS('Test Case Register'!B5:B700,"Attendance",'Test Case Register'!G5:G700,"Fail") -> 0 | I12: =COUNTIFS('Test Case Register'!B5:B700,"Attendance",'Test Case Register'!G5:G700,"Blocked") -> 0 | K12: =IF(E12+G12=0,"-",E12/(E12+G12)) -> -
A13: Expense Claim | C13: 60 | E13: =COUNTIFS('Test Case Register'!B5:B700,"Expense Claim",'Test Case Register'!G5:G700,"Pass") -> 0 | G13: =COUNTIFS('Test Case Register'!B5:B700,"Expense Claim",'Test Case Register'!G5:G700,"Fail") -> 0 | I13: =COUNTIFS('Test Case Register'!B5:B700,"Expense Claim",'Test Case Register'!G5:G700,"Blocked") -> 0 | K13: =IF(E13+G13=0,"-",E13/(E13+G13)) -> -
A14: Leave Application | C14: 65 | E14: =COUNTIFS('Test Case Register'!B5:B700,"Leave Application",'Test Case Register'!G5:G700,"Pass") -> 0 | G14: =COUNTIFS('Test Case Register'!B5:B700,"Leave Application",'Test Case Register'!G5:G700,"Fail") -> 0 | I14: =COUNTIFS('Test Case Register'!B5:B700,"Leave Application",'Test Case Register'!G5:G700,"Blocked") -> 0 | K14: =IF(E14+G14=0,"-",E14/(E14+G14)) -> -
A15: Service Call | C15: 50 | E15: =COUNTIFS('Test Case Register'!B5:B700,"Service Call",'Test Case Register'!G5:G700,"Pass") -> 0 | G15: =COUNTIFS('Test Case Register'!B5:B700,"Service Call",'Test Case Register'!G5:G700,"Fail") -> 0 | I15: =COUNTIFS('Test Case Register'!B5:B700,"Service Call",'Test Case Register'!G5:G700,"Blocked") -> 0 | K15: =IF(E15+G15=0,"-",E15/(E15+G15)) -> -
A18: Results by Module
A19: Module | B19: DocType | C19: Tests | D19: Pass | E19: Fail | F19: Blocked | G19: Pass Rate
A20: Customer Creation & Basic Details | B20: AMC Customers | C20: 4 | D20: =COUNTIFS('Test Case Register'!B5:B700,"AMC Customers",'Test Case Register'!C5:C700,"Customer Creation & Basic Details",'Test Case Register'!G5:G700,"Pass") -> 0 | E20: =COUNTIFS('Test Case Register'!B5:B700,"AMC Customers",'Test Case Register'!C5:C700,"Customer Creation & Basic Details",'Test Case Register'!G5:G700,"Fail") -> 0 | F20: =COUNTIFS('Test Case Register'!B5:B700,"AMC Customers",'Test Case Register'!C5:C700,"Customer Creation & Basic Details",'Test Case Register'!G5:G700,"Blocked") -> 0 | G20: =IF(D20+E20=0,"-",D20/(D20+E20)) -> -
A21: GST Validation | B21: AMC Customers | C21: 5 | D21: =COUNTIFS('Test Case Register'!B5:B700,"AMC Customers",'Test Case Register'!C5:C700,"GST Validation",'Test Case Register'!G5:G700,"Pass") -> 0 | E21: =COUNTIFS('Test Case Register'!B5:B700,"AMC Customers",'Test Case Register'!C5:C700,"GST Validation",'Test Case Register'!G5:G700,"Fail") -> 0 | F21: =COUNTIFS('Test Case Register'!B5:B700,"AMC Customers",'Test Case Register'!C5:C700,"GST Validation",'Test Case Register'!G5:G700,"Blocked") -> 0 | G21: =IF(D21+E21=0,"-",D21/(D21+E21)) -> -
A22: Branch Locations | B22: AMC Customers | C22: 4 | D22: =COUNTIFS('Test Case Register'!B5:B700,"AMC Customers",'Test Case Register'!C5:C700,"Branch Locations",'Test Case Register'!G5:G700,"Pass") -> 0 | E22: =COUNTIFS('Test Case Register'!B5:B700,"AMC Customers",'Test Case Register'!C5:C700,"Branch Locations",'Test Case Register'!G5:G700,"Fail") -> 0 | F22: =COUNTIFS('Test Case Register'!B5:B700,"AMC Customers",'Test Case Register'!C5:C700,"Branch Locations",'Test Case Register'!G5:G700,"Blocked") -> 0 | G22: =IF(D22+E22=0,"-",D22/(D22+E22)) -> -
A23: Contact Details | B23: AMC Customers | C23: 4 | D23: =COUNTIFS('Test Case Register'!B5:B700,"AMC Customers",'Test Case Register'!C5:C700,"Contact Details",'Test Case Register'!G5:G700,"Pass") -> 0 | E23: =COUNTIFS('Test Case Register'!B5:B700,"AMC Customers",'Test Case Register'!C5:C700,"Contact Details",'Test Case Register'!G5:G700,"Fail") -> 0 | F23: =COUNTIFS('Test Case Register'!B5:B700,"AMC Customers",'Test Case Register'!C5:C700,"Contact Details",'Test Case Register'!G5:G700,"Blocked") -> 0 | G23: =IF(D23+E23=0,"-",D23/(D23+E23)) -> -
A24: Connections Tab | B24: AMC Customers | C24: 2 | D24: =COUNTIFS('Test Case Register'!B5:B700,"AMC Customers",'Test Case Register'!C5:C700,"Connections Tab",'Test Case Register'!G5:G700,"Pass") -> 0 | E24: =COUNTIFS('Test Case Register'!B5:B700,"AMC Customers",'Test Case Register'!C5:C700,"Connections Tab",'Test Case Register'!G5:G700,"Fail") -> 0 | F24: =COUNTIFS('Test Case Register'!B5:B700,"AMC Customers",'Test Case Register'!C5:C700,"Connections Tab",'Test Case Register'!G5:G700,"Blocked") -> 0 | G24: =IF(D24+E24=0,"-",D24/(D24+E24)) -> -
A25: Permissions | B25: AMC Customers | C25: 1 | D25: =COUNTIFS('Test Case Register'!B5:B700,"AMC Customers",'Test Case Register'!C5:C700,"Permissions",'Test Case Register'!G5:G700,"Pass") -> 0 | E25: =COUNTIFS('Test Case Register'!B5:B700,"AMC Customers",'Test Case Register'!C5:C700,"Permissions",'Test Case Register'!G5:G700,"Fail") -> 0 | F25: =COUNTIFS('Test Case Register'!B5:B700,"AMC Customers",'Test Case Register'!C5:C700,"Permissions",'Test Case Register'!G5:G700,"Blocked") -> 0 | G25: =IF(D25+E25=0,"-",D25/(D25+E25)) -> -
A26: Data Integrity | B26: AMC Customers | C26: 1 | D26: =COUNTIFS('Test Case Register'!B5:B700,"AMC Customers",'Test Case Register'!C5:C700,"Data Integrity",'Test Case Register'!G5:G700,"Pass") -> 0 | E26: =COUNTIFS('Test Case Register'!B5:B700,"AMC Customers",'Test Case Register'!C5:C700,"Data Integrity",'Test Case Register'!G5:G700,"Fail") -> 0 | F26: =COUNTIFS('Test Case Register'!B5:B700,"AMC Customers",'Test Case Register'!C5:C700,"Data Integrity",'Test Case Register'!G5:G700,"Blocked") -> 0 | G26: =IF(D26+E26=0,"-",D26/(D26+E26)) -> -
A27: Contract Creation | B27: AMC Contract | C27: 5 | D27: =COUNTIFS('Test Case Register'!B5:B700,"AMC Contract",'Test Case Register'!C5:C700,"Contract Creation",'Test Case Register'!G5:G700,"Pass") -> 0 | E27: =COUNTIFS('Test Case Register'!B5:B700,"AMC Contract",'Test Case Register'!C5:C700,"Contract Creation",'Test Case Register'!G5:G700,"Fail") -> 0 | F27: =COUNTIFS('Test Case Register'!B5:B700,"AMC Contract",'Test Case Register'!C5:C700,"Contract Creation",'Test Case Register'!G5:G700,"Blocked") -> 0 | G27: =IF(D27+E27=0,"-",D27/(D27+E27)) -> -
A28: Contract Date Logic | B28: AMC Contract | C28: 3 | D28: =COUNTIFS('Test Case Register'!B5:B700,"AMC Contract",'Test Case Register'!C5:C700,"Contract Date Logic",'Test Case Register'!G5:G700,"Pass") -> 0 | E28: =COUNTIFS('Test Case Register'!B5:B700,"AMC Contract",'Test Case Register'!C5:C700,"Contract Date Logic",'Test Case Register'!G5:G700,"Fail") -> 0 | F28: =COUNTIFS('Test Case Register'!B5:B700,"AMC Contract",'Test Case Register'!C5:C700,"Contract Date Logic",'Test Case Register'!G5:G700,"Blocked") -> 0 | G28: =IF(D28+E28=0,"-",D28/(D28+E28)) -> -
A29: Service Count & Schedule | B29: AMC Contract | C29: 6 | D29: =COUNTIFS('Test Case Register'!B5:B700,"AMC Contract",'Test Case Register'!C5:C700,"Service Count & Schedule",'Test Case Register'!G5:G700,"Pass") -> 0 | E29: =COUNTIFS('Test Case Register'!B5:B700,"AMC Contract",'Test Case Register'!C5:C700,"Service Count & Schedule",'Test Case Register'!G5:G700,"Fail") -> 0 | F29: =COUNTIFS('Test Case Register'!B5:B700,"AMC Contract",'Test Case Register'!C5:C700,"Service Count & Schedule",'Test Case Register'!G5:G700,"Blocked") -> 0 | G29: =IF(D29+E29=0,"-",D29/(D29+E29)) -> -
A30: Customer & Branch Linkage | B30: AMC Contract | C30: 4 | D30: =COUNTIFS('Test Case Register'!B5:B700,"AMC Contract",'Test Case Register'!C5:C700,"Customer & Branch Linkage",'Test Case Register'!G5:G700,"Pass") -> 0 | E30: =COUNTIFS('Test Case Register'!B5:B700,"AMC Contract",'Test Case Register'!C5:C700,"Customer & Branch Linkage",'Test Case Register'!G5:G700,"Fail") -> 0 | F30: =COUNTIFS('Test Case Register'!B5:B700,"AMC Contract",'Test Case Register'!C5:C700,"Customer & Branch Linkage",'Test Case Register'!G5:G700,"Blocked") -> 0 | G30: =IF(D30+E30=0,"-",D30/(D30+E30)) -> -
A31: Contract Status | B31: AMC Contract | C31: 3 | D31: =COUNTIFS('Test Case Register'!B5:B700,"AMC Contract",'Test Case Register'!C5:C700,"Contract Status",'Test Case Register'!G5:G700,"Pass") -> 0 | E31: =COUNTIFS('Test Case Register'!B5:B700,"AMC Contract",'Test Case Register'!C5:C700,"Contract Status",'Test Case Register'!G5:G700,"Fail") -> 0 | F31: =COUNTIFS('Test Case Register'!B5:B700,"AMC Contract",'Test Case Register'!C5:C700,"Contract Status",'Test Case Register'!G5:G700,"Blocked") -> 0 | G31: =IF(D31+E31=0,"-",D31/(D31+E31)) -> -
A32: Submit & Amend Workflow | B32: AMC Contract | C32: 4 | D32: =COUNTIFS('Test Case Register'!B5:B700,"AMC Contract",'Test Case Register'!C5:C700,"Submit & Amend Workflow",'Test Case Register'!G5:G700,"Pass") -> 0 | E32: =COUNTIFS('Test Case Register'!B5:B700,"AMC Contract",'Test Case Register'!C5:C700,"Submit & Amend Workflow",'Test Case Register'!G5:G700,"Fail") -> 0 | F32: =COUNTIFS('Test Case Register'!B5:B700,"AMC Contract",'Test Case Register'!C5:C700,"Submit & Amend Workflow",'Test Case Register'!G5:G700,"Blocked") -> 0 | G32: =IF(D32+E32=0,"-",D32/(D32+E32)) -> -
A33: Company Branch | B33: AMC Contract | C33: 1 | D33: =COUNTIFS('Test Case Register'!B5:B700,"AMC Contract",'Test Case Register'!C5:C700,"Company Branch",'Test Case Register'!G5:G700,"Pass") -> 0 | E33: =COUNTIFS('Test Case Register'!B5:B700,"AMC Contract",'Test Case Register'!C5:C700,"Company Branch",'Test Case Register'!G5:G700,"Fail") -> 0 | F33: =COUNTIFS('Test Case Register'!B5:B700,"AMC Contract",'Test Case Register'!C5:C700,"Company Branch",'Test Case Register'!G5:G700,"Blocked") -> 0 | G33: =IF(D33+E33=0,"-",D33/(D33+E33)) -> -
A34: Service Calls Tab | B34: AMC Contract | C34: 3 | D34: =COUNTIFS('Test Case Register'!B5:B700,"AMC Contract",'Test Case Register'!C5:C700,"Service Calls Tab",'Test Case Register'!G5:G700,"Pass") -> 0 | E34: =COUNTIFS('Test Case Register'!B5:B700,"AMC Contract",'Test Case Register'!C5:C700,"Service Calls Tab",'Test Case Register'!G5:G700,"Fail") -> 0 | F34: =COUNTIFS('Test Case Register'!B5:B700,"AMC Contract",'Test Case Register'!C5:C700,"Service Calls Tab",'Test Case Register'!G5:G700,"Blocked") -> 0 | G34: =IF(D34+E34=0,"-",D34/(D34+E34)) -> -
A35: Cross-DocType Integration | B35: AMC Contract | C35: 3 | D35: =COUNTIFS('Test Case Register'!B5:B700,"AMC Contract",'Test Case Register'!C5:C700,"Cross-DocType Integration",'Test Case Register'!G5:G700,"Pass") -> 0 | E35: =COUNTIFS('Test Case Register'!B5:B700,"AMC Contract",'Test Case Register'!C5:C700,"Cross-DocType Integration",'Test Case Register'!G5:G700,"Fail") -> 0 | F35: =COUNTIFS('Test Case Register'!B5:B700,"AMC Contract",'Test Case Register'!C5:C700,"Cross-DocType Integration",'Test Case Register'!G5:G700,"Blocked") -> 0 | G35: =IF(D35+E35=0,"-",D35/(D35+E35)) -> -
A36: Vendor Creation & Basic Details | B36: Vendor | C36: 4 | D36: =COUNTIFS('Test Case Register'!B5:B700,"Vendor",'Test Case Register'!C5:C700,"Vendor Creation & Basic Details",'Test Case Register'!G5:G700,"Pass") -> 0 | E36: =COUNTIFS('Test Case Register'!B5:B700,"Vendor",'Test Case Register'!C5:C700,"Vendor Creation & Basic Details",'Test Case Register'!G5:G700,"Fail") -> 0 | F36: =COUNTIFS('Test Case Register'!B5:B700,"Vendor",'Test Case Register'!C5:C700,"Vendor Creation & Basic Details",'Test Case Register'!G5:G700,"Blocked") -> 0 | G36: =IF(D36+E36=0,"-",D36/(D36+E36)) -> -
A37: Primary Contact Details | B37: Vendor | C37: 5 | D37: =COUNTIFS('Test Case Register'!B5:B700,"Vendor",'Test Case Register'!C5:C700,"Primary Contact Details",'Test Case Register'!G5:G700,"Pass") -> 0 | E37: =COUNTIFS('Test Case Register'!B5:B700,"Vendor",'Test Case Register'!C5:C700,"Primary Contact Details",'Test Case Register'!G5:G700,"Fail") -> 0 | F37: =COUNTIFS('Test Case Register'!B5:B700,"Vendor",'Test Case Register'!C5:C700,"Primary Contact Details",'Test Case Register'!G5:G700,"Blocked") -> 0 | G37: =IF(D37+E37=0,"-",D37/(D37+E37)) -> -
A38: Tax Identification | B38: Vendor | C38: 4 | D38: =COUNTIFS('Test Case Register'!B5:B700,"Vendor",'Test Case Register'!C5:C700,"Tax Identification",'Test Case Register'!G5:G700,"Pass") -> 0 | E38: =COUNTIFS('Test Case Register'!B5:B700,"Vendor",'Test Case Register'!C5:C700,"Tax Identification",'Test Case Register'!G5:G700,"Fail") -> 0 | F38: =COUNTIFS('Test Case Register'!B5:B700,"Vendor",'Test Case Register'!C5:C700,"Tax Identification",'Test Case Register'!G5:G700,"Blocked") -> 0 | G38: =IF(D38+E38=0,"-",D38/(D38+E38)) -> -
A39: Registered Address | B39: Vendor | C39: 3 | D39: =COUNTIFS('Test Case Register'!B5:B700,"Vendor",'Test Case Register'!C5:C700,"Registered Address",'Test Case Register'!G5:G700,"Pass") -> 0 | E39: =COUNTIFS('Test Case Register'!B5:B700,"Vendor",'Test Case Register'!C5:C700,"Registered Address",'Test Case Register'!G5:G700,"Fail") -> 0 | F39: =COUNTIFS('Test Case Register'!B5:B700,"Vendor",'Test Case Register'!C5:C700,"Registered Address",'Test Case Register'!G5:G700,"Blocked") -> 0 | G39: =IF(D39+E39=0,"-",D39/(D39+E39)) -> -
A40: Address Table | B40: Vendor | C40: 10 | D40: =COUNTIFS('Test Case Register'!B5:B700,"Vendor",'Test Case Register'!C5:C700,"Address Table",'Test Case Register'!G5:G700,"Pass") -> 0 | E40: =COUNTIFS('Test Case Register'!B5:B700,"Vendor",'Test Case Register'!C5:C700,"Address Table",'Test Case Register'!G5:G700,"Fail") -> 0 | F40: =COUNTIFS('Test Case Register'!B5:B700,"Vendor",'Test Case Register'!C5:C700,"Address Table",'Test Case Register'!G5:G700,"Blocked") -> 0 | G40: =IF(D40+E40=0,"-",D40/(D40+E40)) -> -
A41: Data Validation | B41: Vendor | C41: 4 | D41: =COUNTIFS('Test Case Register'!B5:B700,"Vendor",'Test Case Register'!C5:C700,"Data Validation",'Test Case Register'!G5:G700,"Pass") -> 0 | E41: =COUNTIFS('Test Case Register'!B5:B700,"Vendor",'Test Case Register'!C5:C700,"Data Validation",'Test Case Register'!G5:G700,"Fail") -> 0 | F41: =COUNTIFS('Test Case Register'!B5:B700,"Vendor",'Test Case Register'!C5:C700,"Data Validation",'Test Case Register'!G5:G700,"Blocked") -> 0 | G41: =IF(D41+E41=0,"-",D41/(D41+E41)) -> -
A42: Editing & Updates | B42: Vendor | C42: 5 | D42: =COUNTIFS('Test Case Register'!B5:B700,"Vendor",'Test Case Register'!C5:C700,"Editing & Updates",'Test Case Register'!G5:G700,"Pass") -> 0 | E42: =COUNTIFS('Test Case Register'!B5:B700,"Vendor",'Test Case Register'!C5:C700,"Editing & Updates",'Test Case Register'!G5:G700,"Fail") -> 0 | F42: =COUNTIFS('Test Case Register'!B5:B700,"Vendor",'Test Case Register'!C5:C700,"Editing & Updates",'Test Case Register'!G5:G700,"Blocked") -> 0 | G42: =IF(D42+E42=0,"-",D42/(D42+E42)) -> -
A43: Form Actions | B43: Vendor | C43: 5 | D43: =COUNTIFS('Test Case Register'!B5:B700,"Vendor",'Test Case Register'!C5:C700,"Form Actions",'Test Case Register'!G5:G700,"Pass") -> 0 | E43: =COUNTIFS('Test Case Register'!B5:B700,"Vendor",'Test Case Register'!C5:C700,"Form Actions",'Test Case Register'!G5:G700,"Fail") -> 0 | F43: =COUNTIFS('Test Case Register'!B5:B700,"Vendor",'Test Case Register'!C5:C700,"Form Actions",'Test Case Register'!G5:G700,"Blocked") -> 0 | G43: =IF(D43+E43=0,"-",D43/(D43+E43)) -> -
A44: Attendance Creation & Basic Details | B44: Attendance | C44: 6 | D44: =COUNTIFS('Test Case Register'!B5:B700,"Attendance",'Test Case Register'!C5:C700,"Attendance Creation & Basic Details",'Test Case Register'!G5:G700,"Pass") -> 0 | E44: =COUNTIFS('Test Case Register'!B5:B700,"Attendance",'Test Case Register'!C5:C700,"Attendance Creation & Basic Details",'Test Case Register'!G5:G700,"Fail") -> 0 | F44: =COUNTIFS('Test Case Register'!B5:B700,"Attendance",'Test Case Register'!C5:C700,"Attendance Creation & Basic Details",'Test Case Register'!G5:G700,"Blocked") -> 0 | G44: =IF(D44+E44=0,"-",D44/(D44+E44)) -> -
...

Sheet Priority Analysis
A1: AMC Core — Master Priority & Coverage Analysis
A2: All 320 test cases sorted by priority. Execute Critical first across all DocTypes.
A4: Priority | B4: Test ID | C4: DocType | D4: Module | E4: Test Case Title | F4: Business Rule
A5: Critical | B5: CUST-001 | C5: AMC Customers | D5: Customer Creation & Basic Details | E5: Create customer with Customer Name only (minimum required) | F5: BR-CUST-01
A6: Critical | B6: CUST-002 | C6: AMC Customers | D6: Customer Creation & Basic Details | E6: Create Company customer with all basic fields (Name, Type, GST, PAN) | F6: BR-CUST-01, BR-CUST-02
A7: Critical | B7: CUST-005 | C7: AMC Customers | D7: GST Validation | E7: Valid 15-character GSTIN is accepted | F7: BR-CUST-03
A8: Critical | B8: CUST-006 | C8: AMC Customers | D8: GST Validation | E8: Invalid GST format is rejected with specific error message | F8: BR-CUST-03
A9: Critical | B9: CUST-007 | C9: AMC Customers | D9: GST Validation | E9: Duplicate GSTIN across two customers is blocked | F9: BR-CUST-04
A10: Critical | B10: CUST-010 | C10: AMC Customers | D10: Branch Locations | E10: Add single branch location to customer | F10: BR-CUST-06
A11: Critical | B11: CUST-014 | C11: AMC Customers | D11: Contact Details | E11: Add primary contact to customer | F11: BR-CUST-07
A12: Critical | B12: CUST-020 | C12: AMC Customers | D12: Permissions | E12: Technician role can only READ AMC Customers | F12: BR-CUST-11
A13: Critical | B13: CON-001 | C13: AMC Contract | D13: Contract Creation | E13: Create AMC Contract with all mandatory fields | F13: BR-CON-01
A14: Critical | B14: CON-002 | C14: AMC Contract | D14: Contract Creation | E14: Start Date is mandatory — save fails without it | F14: BR-CON-01
A15: Critical | B15: CON-003 | C15: AMC Contract | D15: Contract Creation | E15: End Date is mandatory — save fails without it | F15: BR-CON-01
... A324: Medium | B324: SC-038 | C324: Service Call | D324: Documentation | E324: Delete attached document from Service Call | F324: BR-SC-12
A327: Priority Summary
A328: Priority | B328: Count | C328: % of Total
A329: Critical | B329: 168 | C329: 0.525
A330: High | B330: 113 | C330: 0.353125
A331: Medium | B331: 39 | C331: 0.121875

Sheet Business Rules
A1: AMC Core — Master Business Rules Reference
A2: 98 business rules across 7 DocTypes. Every test case traces to exactly one rule.
A4: Rule ID | B4: DocType | C4: Category | D4: Rule Name | E4: Description / ERPNext v15 Field Details | F4: Test Cases
A5: ▌ AMC Customers
A6: BR-CUST-01 | B6: AMC Customers | C6: Creation | D6: Customer Name is primary identifier | E6: Customer Name is core searchable field. Naming series CUST-.####. auto-assigns ID. | F6: CUST-001, CUST-002
A7: BR-CUST-02 | B7: AMC Customers | C7: Creation | D7: Customer Type classifies legal entity | E7: Must be Company, Individual, or Partnership. Determines tax and contact rules. | F7: CUST-003, CUST-004
A8: BR-CUST-03 | B8: AMC Customers | C8: GST Validation | D8: GST must match 15-char regex or be blank | E8: Regex: ^$|^[0-9]{2}[A-Z]{4}[A-Z0-9]{1}[0-9]{4}[A-Z]{1}[1-9A-Z]{1}[A-Z]{1}[A-Z0-9]{1}$. Error message shown on mismatch. | F8: CUST-005, CUST-006, CUST-008
A9: BR-CUST-04 | B9: AMC Customers | C9: GST Validation | D9: GST is unique across all customers | E9: unique:1 on GST field. Two customers cannot share same GSTIN. | F9: CUST-007
A10: BR-CUST-05 | B10: AMC Customers | C10: PAN Validation | D10: PAN is unique across all customers | E10: unique:1 on PAN field. Two customers cannot share same PAN. | F10: CUST-009
A11: BR-CUST-06 | B11: AMC Customers | C11: Branches | D11: Branch Locations define service sites | E11: Customer Branch Mapping child table: Branch + Address. Branches link to Contracts. | F11: CUST-010, CUST-011, CUST-012, CUST-013
A12: BR-CUST-07 | B12: AMC Customers | C12: Contacts | D12: Contact Details store per-branch persons | E12: Customer Contact Mapping: Name, Mobile, Email, Branch, Is Primary. Drives contract contact selection. | F12: CUST-014, CUST-016, CUST-017
A13: BR-CUST-08 | B13: AMC Customers | C13: Contacts | D13: Only one Is Primary contact per customer | E13: Business rule: Is Primary uniqueness per customer to avoid escalation ambiguity. | F13: CUST-015
A14: BR-CUST-09 | B14: AMC Customers | C14: Connections | D14: Customer links to Contracts and Service Calls | E14: links[]: AMC Contract.customer + Service Call.customer. Visible in Connections tab HTML. | F14: CUST-018, CUST-019
A15: BR-CUST-10 | B15: AMC Customers | C15: Data Integrity | D15: Customer with active contracts cannot be deleted | E15: Referential integrity: deletion blocked if AMC Contracts reference this customer. | F15: CUST-021, CON-031
A16: BR-CUST-11 | B16: AMC Customers | C16: Permissions | D16: Technician has read-only access to customers | E16: Permissions: Technician read:1 only. No create, write, delete on AMC Customers. | F16: CUST-020
A17: ▌ AMC Contract
A18: BR-CON-01 | B18: AMC Contract | C18: Mandatory Fields | D18: Start Date, End Date, No of Services required | E18: reqd:1 on all three. Save is blocked without any of these fields. | F18: CON-001, CON-002, CON-003, CON-004
A19: BR-CON-02 | B19: AMC Contract | C19: Auto-Naming | D19: Contract name follows AMC-.YY.MM.-.#### series | E19: naming_series: "AMC-.YY.MM.-.####". Provides month-stamped, chronological IDs. | F19: CON-005
A20: BR-CON-03 | B20: AMC Contract | C20: Date Logic | D20: End Date must be >= Start Date | E20: Business rule: end < start must be rejected. Same-day and multi-year spans are valid. | F20: CON-006, CON-007, CON-008
A21: BR-CON-04 | B21: AMC Contract | C21: Service Count | D21: No of Services drives Maintenance Schedule rows | E21: Select 1-12. Must generate exactly that many rows in Maintenance Schedule child table. | F21: CON-009 to CON-013, CON-029
A22: BR-CON-05 | B22: AMC Contract | C22: Service Count | D22: Schedule dates must fall within contract period | E22: Each generated date >= start_date and <= end_date. | F22: CON-012
A23: BR-CON-06 | B23: AMC Contract | C23: Customer Linkage | D23: Branch filtered by selected Customer | E23: link_filters: Customer Branch.customer = doc.customer. Branch only shows that customer's branches. | F23: CON-015, CON-016, CON-017
A24: BR-CON-07 | B24: AMC Contract | C24: Contact Linkage | D24: Contact Person filtered by selected Branch | E24: link_filters: Customer Contact.branch = doc.branch. Mobile auto-fetched via fetch_from. | F24: CON-018, CUST-016, CUST-017
A25: BR-CON-08 | B25: AMC Contract | C25: Equipment | D25: Maintenance Schedule stores equipment per visit | E25: Child table columns: Equipment, Quantity, Unit, Description. Per-visit specification. | F25: CON-014, CON-026
A26: BR-CON-09 | B26: AMC Contract | C26: Status | D26: Status: blank / Active / Inactive | E26: Select field. Blank by default. Active enables service call dispatch; Inactive suspends it. | F26: CON-019, CON-020, CON-021
A27: BR-CON-10 | B27: AMC Contract | C27: Workflow | D27: is_submittable: Draft > Submit > Cancel | E27: is_submittable:1. Submitted = read-only. Cancelled = immutable. Technician cannot cancel. | F27: CON-022, CON-023, CON-025
A28: BR-CON-11 | B28: AMC Contract | C28: Workflow | D28: Submitted contract can be Amended | E28: amended_from field links to original. Amend creates new draft; original is cancelled on re-submit. | F28: CON-024
A29: BR-CON-12 | B29: AMC Contract | C29: Service Calls | D29: Service Calls tab shows generated calls | E29: service_calls_html renders calls. Count must equal No of Services after processing. | F29: CON-027, CON-028, CON-029
... A31: BR-CON-14 | B31: AMC Contract | C31: Permissions | D31: Technician: create/write/submit, no cancel/delete | E31: Technician permissions: create, write, read, submit, email, export, print, share, select. No cancel or delete. | F31: CON-032, CUST-020
A32: ▌ Vendor
A33: BR-VEN-01 | B33: Vendor | C33: Creation | D33: Vendor Name is mandatory | E33: Vendor Name is the primary identifier. Save is blocked without it. | F33: VEN-001, VEN-002, VEN-027, VEN-036
A34: BR-VEN-02 | B34: Vendor | C34: Creation | D34: Vendor Type: Company or Individual | E34: Type field classifies the vendor entity. Defaults to Company if blank. | F34: VEN-003, VEN-004, VEN-029, VEN-030
A35: BR-VEN-03 | B35: Vendor | C35: Primary Contact | D35: Contact details validated (phone, email) | E35: Mobile No and Email must match valid formats. | F35: VEN-005 to VEN-009
A36: BR-VEN-04 | B36: Vendor | C36: Tax ID | D36: PAN must match valid format or be blank | E36: PAN: 10-char alphanumeric. Optional field — blank is allowed. | F36: VEN-010, VEN-011, VEN-013
A37: BR-VEN-05 | B37: Vendor | C37: Tax ID | D37: PAN is unique across all vendors | E37: unique:1 on PAN. Two vendors cannot share the same PAN. | F37: VEN-012
A38: BR-VEN-06 | B38: Vendor | C38: Address | D38: Registered Address is a free-text field | E38: Text area, accepts special characters. Saved as-is. | F38: VEN-014, VEN-015, VEN-016
A39: BR-VEN-07 | B39: Vendor | C39: Address Table | D39: Address table stores multiple addresses | E39: Child table: Name, City, State, Mobile No per row. | F39: VEN-017 to VEN-022, VEN-025
A40: BR-VEN-08 | B40: Vendor | C40: Address Table | D40: GST No in address row validated | E40: GST must be valid 15-char GSTIN format per address row. | F40: VEN-023, VEN-024
A41: BR-VEN-09 | B41: Vendor | C41: Address Table | D41: Duplicate GST across address rows is blocked | E41: Each address row GST must be unique within the vendor. | F41: VEN-026
A42: BR-VEN-10 | B42: Vendor | C42: Editing | D42: All fields editable after creation | E42: Vendor records can be updated at any time. | F42: VEN-031 to VEN-035
...
